[2025-07-25T20:02:21.398+0000] {local_task_job_runner.py:120} INFO - ::group::Pre task execution logs
[2025-07-25T20:02:21.472+0000] {taskinstance.py:2076} INFO - Dependencies all met for dep_context=non-requeueable deps ti=<TaskInstance: sample_ETL.load_order_and_delivery_data manual__2025-07-25T20:02:09.306245+00:00 [queued]>
[2025-07-25T20:02:21.484+0000] {taskinstance.py:2076} INFO - Dependencies all met for dep_context=requeueable deps ti=<TaskInstance: sample_ETL.load_order_and_delivery_data manual__2025-07-25T20:02:09.306245+00:00 [queued]>
[2025-07-25T20:02:21.485+0000] {taskinstance.py:2306} INFO - Starting attempt 1 of 1
[2025-07-25T20:02:21.526+0000] {taskinstance.py:2330} INFO - Executing <Task(PythonOperator): load_order_and_delivery_data> on 2025-07-25 20:02:09.306245+00:00
[2025-07-25T20:02:21.535+0000] {logging_mixin.py:188} WARNING - /home/***/.local/lib/python3.12/site-packages/***/task/task_runner/standard_task_runner.py:61 DeprecationWarning: This process (pid=251) is multi-threaded, use of fork() may lead to deadlocks in the child.
[2025-07-25T20:02:21.536+0000] {standard_task_runner.py:63} INFO - Started process 252 to run task
[2025-07-25T20:02:21.535+0000] {standard_task_runner.py:90} INFO - Running: ['***', 'tasks', 'run', 'sample_ETL', 'load_order_and_delivery_data', 'manual__2025-07-25T20:02:09.306245+00:00', '--job-id', '46', '--raw', '--subdir', 'DAGS_FOLDER/sample_ETL.py', '--cfg-path', '/tmp/tmp4qb75qst']
[2025-07-25T20:02:21.537+0000] {standard_task_runner.py:91} INFO - Job 46: Subtask load_order_and_delivery_data
[2025-07-25T20:02:21.642+0000] {logging_mixin.py:188} WARNING - /home/***/.local/lib/python3.12/site-packages/***/settings.py:195 DeprecationWarning: The sql_alchemy_conn option in [core] has been moved to the sql_alchemy_conn option in [database] - the old setting has been used, but please update your config.
[2025-07-25T20:02:21.760+0000] {task_command.py:426} INFO - Running <TaskInstance: sample_ETL.load_order_and_delivery_data manual__2025-07-25T20:02:09.306245+00:00 [running]> on host 9d522913c5f5
[2025-07-25T20:02:22.128+0000] {taskinstance.py:2648} INFO - Exporting env vars: AIRFLOW_CTX_DAG_OWNER='***' AIRFLOW_CTX_DAG_ID='sample_ETL' AIRFLOW_CTX_TASK_ID='load_order_and_delivery_data' AIRFLOW_CTX_EXECUTION_DATE='2025-07-25T20:02:09.306245+00:00' AIRFLOW_CTX_TRY_NUMBER='1' AIRFLOW_CTX_DAG_RUN_ID='manual__2025-07-25T20:02:09.306245+00:00'
[2025-07-25T20:02:22.132+0000] {taskinstance.py:430} INFO - ::endgroup::
[2025-07-25T20:02:22.167+0000] {logging_mixin.py:188} INFO - ðŸš€ Starting load_order_and_delivery_data
[2025-07-25T20:02:22.189+0000] {conn.py:396} INFO - <BrokerConnection client_id=kafka-python-producer-1, node_id=bootstrap-0 host=kafka:9092 <connecting> [IPv4 ('172.18.0.7', 9092)]>: connecting to kafka:9092 [('172.18.0.7', 9092) IPv4]
[2025-07-25T20:02:22.948+0000] {conn.py:618} INFO - <BrokerConnection client_id=kafka-python-producer-1, node_id=bootstrap-0 host=kafka:9092 <checking_api_versions_recv> [IPv4 ('172.18.0.7', 9092)]>: Broker version identified as 2.6
[2025-07-25T20:02:22.949+0000] {conn.py:457} INFO - <BrokerConnection client_id=kafka-python-producer-1, node_id=bootstrap-0 host=kafka:9092 <connected> [IPv4 ('172.18.0.7', 9092)]>: Connection complete.
[2025-07-25T20:02:23.312+0000] {conn.py:396} INFO - <BrokerConnection client_id=kafka-python-producer-1, node_id=1 host=kafka:9092 <connecting> [IPv4 ('172.18.0.7', 9092)]>: connecting to kafka:9092 [('172.18.0.7', 9092) IPv4]
[2025-07-25T20:02:23.315+0000] {conn.py:457} INFO - <BrokerConnection client_id=kafka-python-producer-1, node_id=1 host=kafka:9092 <connected> [IPv4 ('172.18.0.7', 9092)]>: Connection complete.
[2025-07-25T20:02:23.316+0000] {conn.py:945} INFO - <BrokerConnection client_id=kafka-python-producer-1, node_id=bootstrap-0 host=kafka:9092 <connected> [IPv4 ('172.18.0.7', 9092)]>: Closing connection. 
[2025-07-25T20:02:24.011+0000] {cluster.py:313} WARNING - Topic orders_topic is not available during auto-create initialization
[2025-07-25T20:02:24.129+0000] {cluster.py:313} WARNING - Topic orders_topic is not available during auto-create initialization
[2025-07-25T20:02:24.242+0000] {cluster.py:313} WARNING - Topic orders_topic is not available during auto-create initialization
[2025-07-25T20:02:24.353+0000] {cluster.py:313} WARNING - Topic orders_topic is not available during auto-create initialization
[2025-07-25T20:02:24.463+0000] {cluster.py:313} WARNING - Topic orders_topic is not available during auto-create initialization
[2025-07-25T20:02:24.651+0000] {cluster.py:313} WARNING - Topic orders_topic is not available during auto-create initialization
[2025-07-25T20:02:24.763+0000] {cluster.py:313} WARNING - Topic orders_topic is not available during auto-create initialization
[2025-07-25T20:02:24.877+0000] {cluster.py:313} WARNING - Topic orders_topic is not available during auto-create initialization
[2025-07-25T20:02:24.988+0000] {cluster.py:313} WARNING - Topic orders_topic is not available during auto-create initialization
[2025-07-25T20:02:25.274+0000] {logging_mixin.py:188} INFO - âœ… Produced 126 records to topic 'orders_topic'
[2025-07-25T20:02:25.275+0000] {logging_mixin.py:188} INFO - orders producer completed
[2025-07-25T20:02:25.474+0000] {cluster.py:313} WARNING - Topic delivery_topic is not available during auto-create initialization
[2025-07-25T20:02:25.654+0000] {logging_mixin.py:188} INFO - âœ… Produced 126 records to topic 'delivery_topic'
[2025-07-25T20:02:25.655+0000] {logging_mixin.py:188} INFO - delivery producer completed
[2025-07-25T20:02:30.658+0000] {conn.py:396} INFO - <BrokerConnection client_id=kafka-python-2.2.15, node_id=bootstrap-0 host=kafka:9092 <connecting> [IPv4 ('172.18.0.7', 9092)]>: connecting to kafka:9092 [('172.18.0.7', 9092) IPv4]
[2025-07-25T20:02:30.666+0000] {conn.py:618} INFO - <BrokerConnection client_id=kafka-python-2.2.15, node_id=bootstrap-0 host=kafka:9092 <checking_api_versions_recv> [IPv4 ('172.18.0.7', 9092)]>: Broker version identified as 2.6
[2025-07-25T20:02:30.667+0000] {conn.py:457} INFO - <BrokerConnection client_id=kafka-python-2.2.15, node_id=bootstrap-0 host=kafka:9092 <connected> [IPv4 ('172.18.0.7', 9092)]>: Connection complete.
[2025-07-25T20:02:30.668+0000] {subscription_state.py:181} INFO - Updating subscribed topics to: ('orders_topic',)
[2025-07-25T20:02:30.738+0000] {conn.py:396} INFO - <BrokerConnection client_id=kafka-python-2.2.15, node_id=1 host=kafka:9092 <connecting> [IPv4 ('172.18.0.7', 9092)]>: connecting to kafka:9092 [('172.18.0.7', 9092) IPv4]
[2025-07-25T20:02:30.739+0000] {conn.py:457} INFO - <BrokerConnection client_id=kafka-python-2.2.15, node_id=1 host=kafka:9092 <connected> [IPv4 ('172.18.0.7', 9092)]>: Connection complete.
[2025-07-25T20:02:30.740+0000] {conn.py:945} INFO - <BrokerConnection client_id=kafka-python-2.2.15, node_id=bootstrap-0 host=kafka:9092 <connected> [IPv4 ('172.18.0.7', 9092)]>: Closing connection. 
[2025-07-25T20:02:33.440+0000] {cluster.py:401} INFO - Coordinator for group/etl_group is ('coordinator-1', 'kafka', 9092, None)
[2025-07-25T20:02:33.441+0000] {base.py:788} INFO - Discovered coordinator coordinator-1 for group etl_group
[2025-07-25T20:02:33.442+0000] {base.py:848} INFO - Starting new heartbeat thread
[2025-07-25T20:02:33.444+0000] {consumer.py:365} INFO - Revoking previously assigned partitions () for group etl_group
[2025-07-25T20:02:33.445+0000] {base.py:419} INFO - Failed to join group etl_group: NodeNotReadyError: coordinator-1
[2025-07-25T20:02:33.447+0000] {conn.py:396} INFO - <BrokerConnection client_id=kafka-python-2.2.15, node_id=coordinator-1 host=kafka:9092 <connecting> [IPv4 ('172.18.0.7', 9092)]>: connecting to kafka:9092 [('172.18.0.7', 9092) IPv4]
[2025-07-25T20:02:33.449+0000] {conn.py:457} INFO - <BrokerConnection client_id=kafka-python-2.2.15, node_id=coordinator-1 host=kafka:9092 <connected> [IPv4 ('172.18.0.7', 9092)]>: Connection complete.
[2025-07-25T20:02:33.550+0000] {base.py:532} INFO - (Re-)joining group etl_group
[2025-07-25T20:02:34.430+0000] {base.py:637} INFO - Received member id kafka-python-2.2.15-196a8873-4d98-444f-b24c-814201aa3e62 for group etl_group; will retry join-group
[2025-07-25T20:02:34.431+0000] {base.py:419} INFO - Failed to join group etl_group: [Error 79] MemberIdRequiredError
[2025-07-25T20:02:34.432+0000] {base.py:532} INFO - (Re-)joining group etl_group
[2025-07-25T20:02:37.554+0000] {base.py:594} INFO - Successfully joined group etl_group <Generation 1 (member_id: kafka-python-2.2.15-196a8873-4d98-444f-b24c-814201aa3e62, protocol: range)>
[2025-07-25T20:02:37.555+0000] {base.py:596} INFO - Elected group leader -- performing partition assignments using range
[2025-07-25T20:02:37.646+0000] {subscription_state.py:254} INFO - Updated partition assignment: [('orders_topic', 0)]
[2025-07-25T20:02:37.647+0000] {consumer.py:249} INFO - Setting newly assigned partitions (('orders_topic', 0),) for group etl_group
[2025-07-25T20:02:37.750+0000] {fetcher.py:418} INFO - Resetting offset for partition ('orders_topic', 0) to offset 0.
[2025-07-25T20:02:38.005+0000] {taskinstance.py:441} INFO - ::group::Post task execution logs
[2025-07-25T20:02:38.009+0000] {taskinstance.py:2905} ERROR - Task failed with exception
Traceback (most recent call last):
  File "/home/airflow/.local/lib/python3.12/site-packages/mysql/connector/connection_cext.py", line 697, in cmd_query
    self._cmysql.query(
_mysql_connector.MySQLInterfaceError: Column count doesn't match value count at row 1

The above exception was the direct cause of the following exception:

Traceback (most recent call last):
  File "/home/airflow/.local/lib/python3.12/site-packages/airflow/models/taskinstance.py", line 465, in _execute_task
    result = _execute_callable(context=context, **execute_callable_kwargs)
             ^^^^^^^^^^^^^^^^^^^^^^^^^^^^^^^^^^^^^^^^^^^^^^^^^^^^^^^^^^^^^
  File "/home/airflow/.local/lib/python3.12/site-packages/airflow/models/taskinstance.py", line 432, in _execute_callable
    return execute_callable(context=context, **execute_callable_kwargs)
           ^^^^^^^^^^^^^^^^^^^^^^^^^^^^^^^^^^^^^^^^^^^^^^^^^^^^^^^^^^^^
  File "/home/airflow/.local/lib/python3.12/site-packages/airflow/models/baseoperator.py", line 400, in wrapper
    return func(self, *args, **kwargs)
           ^^^^^^^^^^^^^^^^^^^^^^^^^^^
  File "/home/airflow/.local/lib/python3.12/site-packages/airflow/operators/python.py", line 235, in execute
    return_value = self.execute_callable()
                   ^^^^^^^^^^^^^^^^^^^^^^^
  File "/home/airflow/.local/lib/python3.12/site-packages/airflow/operators/python.py", line 252, in execute_callable
    return self.python_callable(*self.op_args, **self.op_kwargs)
           ^^^^^^^^^^^^^^^^^^^^^^^^^^^^^^^^^^^^^^^^^^^^^^^^^^^^^
  File "/opt/airflow/dags/script2.py", line 79, in load_order_and_delivery_data
    consume_and_insert(ORDERS_TOPIC, 'orders')
  File "/opt/airflow/dags/script2.py", line 48, in consume_and_insert
    cursor.execute(query, record)
  File "/home/airflow/.local/lib/python3.12/site-packages/mysql/connector/cursor_cext.py", line 372, in execute
    result = self._cnx.cmd_query(
             ^^^^^^^^^^^^^^^^^^^^
  File "/home/airflow/.local/lib/python3.12/site-packages/mysql/connector/opentelemetry/context_propagation.py", line 111, in wrapper
    result = method(cnx, *args, **kwargs)
             ^^^^^^^^^^^^^^^^^^^^^^^^^^^^
  File "/home/airflow/.local/lib/python3.12/site-packages/mysql/connector/connection_cext.py", line 705, in cmd_query
    raise get_mysql_exception(
mysql.connector.errors.DataError: 1136 (21S01): Column count doesn't match value count at row 1
[2025-07-25T20:02:38.388+0000] {taskinstance.py:1206} INFO - Marking task as FAILED. dag_id=sample_ETL, task_id=load_order_and_delivery_data, run_id=manual__2025-07-25T20:02:09.306245+00:00, execution_date=20250725T200209, start_date=20250725T200221, end_date=20250725T200238
[2025-07-25T20:02:38.488+0000] {standard_task_runner.py:110} ERROR - Failed to execute job 46 for task load_order_and_delivery_data (1136 (21S01): Column count doesn't match value count at row 1; 252)
[2025-07-25T20:02:38.528+0000] {local_task_job_runner.py:240} INFO - Task exited with return code 1
[2025-07-25T20:02:38.606+0000] {taskinstance.py:3498} INFO - 0 downstream tasks scheduled from follow-on schedule check
[2025-07-25T20:02:38.631+0000] {local_task_job_runner.py:222} INFO - ::endgroup::
