[2025-07-26T13:02:10.783+0000] {local_task_job_runner.py:120} INFO - ::group::Pre task execution logs
[2025-07-26T13:02:10.858+0000] {taskinstance.py:2076} INFO - Dependencies all met for dep_context=non-requeueable deps ti=<TaskInstance: sample_ETL.process_final_logic manual__2025-07-26T13:01:15.635484+00:00 [queued]>
[2025-07-26T13:02:10.871+0000] {taskinstance.py:2076} INFO - Dependencies all met for dep_context=requeueable deps ti=<TaskInstance: sample_ETL.process_final_logic manual__2025-07-26T13:01:15.635484+00:00 [queued]>
[2025-07-26T13:02:10.872+0000] {taskinstance.py:2306} INFO - Starting attempt 1 of 1
[2025-07-26T13:02:10.929+0000] {taskinstance.py:2330} INFO - Executing <Task(PythonOperator): process_final_logic> on 2025-07-26 13:01:15.635484+00:00
[2025-07-26T13:02:10.943+0000] {logging_mixin.py:188} WARNING - /home/***/.local/lib/python3.12/site-packages/***/task/task_runner/standard_task_runner.py:61 DeprecationWarning: This process (pid=223) is multi-threaded, use of fork() may lead to deadlocks in the child.
[2025-07-26T13:02:10.943+0000] {standard_task_runner.py:90} INFO - Running: ['***', 'tasks', 'run', 'sample_ETL', 'process_final_logic', 'manual__2025-07-26T13:01:15.635484+00:00', '--job-id', '85', '--raw', '--subdir', 'DAGS_FOLDER/sample_ETL.py', '--cfg-path', '/tmp/tmphvfh0puj']
[2025-07-26T13:02:10.946+0000] {standard_task_runner.py:63} INFO - Started process 227 to run task
[2025-07-26T13:02:10.947+0000] {standard_task_runner.py:91} INFO - Job 85: Subtask process_final_logic
[2025-07-26T13:02:11.088+0000] {logging_mixin.py:188} WARNING - /home/***/.local/lib/python3.12/site-packages/***/settings.py:195 DeprecationWarning: The sql_alchemy_conn option in [core] has been moved to the sql_alchemy_conn option in [database] - the old setting has been used, but please update your config.
[2025-07-26T13:02:11.213+0000] {task_command.py:426} INFO - Running <TaskInstance: sample_ETL.process_final_logic manual__2025-07-26T13:01:15.635484+00:00 [running]> on host 88b2e53952eb
[2025-07-26T13:02:11.561+0000] {taskinstance.py:2648} INFO - Exporting env vars: AIRFLOW_CTX_DAG_OWNER='***' AIRFLOW_CTX_DAG_ID='sample_ETL' AIRFLOW_CTX_TASK_ID='process_final_logic' AIRFLOW_CTX_EXECUTION_DATE='2025-07-26T13:01:15.635484+00:00' AIRFLOW_CTX_TRY_NUMBER='1' AIRFLOW_CTX_DAG_RUN_ID='manual__2025-07-26T13:01:15.635484+00:00'
[2025-07-26T13:02:11.563+0000] {taskinstance.py:430} INFO - ::endgroup::
[2025-07-26T13:02:11.600+0000] {logging_mixin.py:188} INFO - Error occurred: 2003 (HY000): Can't connect to MySQL server on 'localhost:3306' (111)
[2025-07-26T13:02:11.601+0000] {taskinstance.py:441} INFO - ::group::Post task execution logs
[2025-07-26T13:02:11.601+0000] {taskinstance.py:2905} ERROR - Task failed with exception
Traceback (most recent call last):
  File "/home/airflow/.local/lib/python3.12/site-packages/mysql/connector/connection_cext.py", line 327, in _open_connection
    self._cmysql.connect(**cnx_kwargs)
_mysql_connector.MySQLInterfaceError: Can't connect to MySQL server on 'localhost:3306' (111)

The above exception was the direct cause of the following exception:

Traceback (most recent call last):
  File "/opt/airflow/dags/script3.py", line 7, in process_final_logic
    conn = mysql.connector.connect(
           ^^^^^^^^^^^^^^^^^^^^^^^^
  File "/home/airflow/.local/lib/python3.12/site-packages/mysql/connector/pooling.py", line 322, in connect
    return CMySQLConnection(*args, **kwargs)
           ^^^^^^^^^^^^^^^^^^^^^^^^^^^^^^^^^
  File "/home/airflow/.local/lib/python3.12/site-packages/mysql/connector/connection_cext.py", line 144, in __init__
    self.connect(**kwargs)
  File "/home/airflow/.local/lib/python3.12/site-packages/mysql/connector/abstracts.py", line 1360, in connect
    self._open_connection()
  File "/home/airflow/.local/lib/python3.12/site-packages/mysql/connector/connection_cext.py", line 332, in _open_connection
    raise get_mysql_exception(
mysql.connector.errors.DatabaseError: 2003 (HY000): Can't connect to MySQL server on 'localhost:3306' (111)

During handling of the above exception, another exception occurred:

Traceback (most recent call last):
  File "/opt/airflow/dags/script3.py", line 83, in process_final_logic
    if conn:
       ^^^^
UnboundLocalError: cannot access local variable 'conn' where it is not associated with a value

During handling of the above exception, another exception occurred:

Traceback (most recent call last):
  File "/home/airflow/.local/lib/python3.12/site-packages/airflow/models/taskinstance.py", line 465, in _execute_task
    result = _execute_callable(context=context, **execute_callable_kwargs)
             ^^^^^^^^^^^^^^^^^^^^^^^^^^^^^^^^^^^^^^^^^^^^^^^^^^^^^^^^^^^^^
  File "/home/airflow/.local/lib/python3.12/site-packages/airflow/models/taskinstance.py", line 432, in _execute_callable
    return execute_callable(context=context, **execute_callable_kwargs)
           ^^^^^^^^^^^^^^^^^^^^^^^^^^^^^^^^^^^^^^^^^^^^^^^^^^^^^^^^^^^^
  File "/home/airflow/.local/lib/python3.12/site-packages/airflow/models/baseoperator.py", line 400, in wrapper
    return func(self, *args, **kwargs)
           ^^^^^^^^^^^^^^^^^^^^^^^^^^^
  File "/home/airflow/.local/lib/python3.12/site-packages/airflow/operators/python.py", line 235, in execute
    return_value = self.execute_callable()
                   ^^^^^^^^^^^^^^^^^^^^^^^
  File "/home/airflow/.local/lib/python3.12/site-packages/airflow/operators/python.py", line 252, in execute_callable
    return self.python_callable(*self.op_args, **self.op_kwargs)
           ^^^^^^^^^^^^^^^^^^^^^^^^^^^^^^^^^^^^^^^^^^^^^^^^^^^^^
  File "/opt/airflow/dags/script3.py", line 86, in process_final_logic
    if cursor:
       ^^^^^^
UnboundLocalError: cannot access local variable 'cursor' where it is not associated with a value
[2025-07-26T13:02:11.673+0000] {taskinstance.py:1206} INFO - Marking task as FAILED. dag_id=sample_ETL, task_id=process_final_logic, run_id=manual__2025-07-26T13:01:15.635484+00:00, execution_date=20250726T130115, start_date=20250726T130210, end_date=20250726T130211
[2025-07-26T13:02:11.722+0000] {standard_task_runner.py:110} ERROR - Failed to execute job 85 for task process_final_logic (cannot access local variable 'cursor' where it is not associated with a value; 227)
[2025-07-26T13:02:11.766+0000] {local_task_job_runner.py:240} INFO - Task exited with return code 1
[2025-07-26T13:02:11.896+0000] {taskinstance.py:3498} INFO - 0 downstream tasks scheduled from follow-on schedule check
[2025-07-26T13:02:11.899+0000] {local_task_job_runner.py:222} INFO - ::endgroup::
